Workbook
Name curr: IS!$AI$4

Sheet IS
B2: Name
B3: Income statement | AI3: <<Do not delete>>
B4: INR million | H4: % to revenue | M4: % change y-o-y | AI4: {=_xlfn.IFS(B4="INR",10^0,B4="INR lakhs",10^5,B4="INR million",10^6)} -> 1000000
B5: Particulars | C5: FY22 | D5: FY23 | E5: FY24 | F5: FY25 | G5: FY26 | H5: =C5 -> FY22 | I5: =D5 -> FY23 | J5: =E5 -> FY24 | K5: =F5 -> FY25 | L5: =G5 -> FY26 | M5: =I5 -> FY23 | N5: =J5 -> FY24 | O5: =K5 -> FY25 | P5: =L5 -> FY26 | AH5: INR
B6: Revenue from operations | C6: =((Sch.!C250))/(curr) -> 0 | D6: =((Sch.!D250))/(curr) -> 0 | E6: =((Sch.!E250))/(curr) -> 0 | F6: =((Sch.!F250))/(curr) -> 0 | G6: =((Sch.!G250))/(curr) -> 0 | H6: =IFERROR(C6/C$7,0) -> 0 | I6: =IFERROR(D6/D$7,0) -> 0 | J6: =IFERROR(E6/E$7,0) -> 0 | K6: =IFERROR(F6/F$7,0) -> 0 | L6: =IFERROR(G6/G$7,0) -> 0 | M6: =+IFERROR((D6/C6)-1,0) -> 0 | N6: =+IFERROR((E6/D6)-1,0) -> 0 | O6: =+IFERROR((F6/E6)-1,0) -> 0 | P6: =+IFERROR((G6/F6)-1,0) -> 0 | AH6: INR lakhs
B7: Total revenue | C7: =SUM(C6:C6) -> 0 | D7: =SUM(D6:D6) -> 0 | E7: =SUM(E6:E6) -> 0 | F7: =SUM(F6:F6) -> 0 | G7: =SUM(G6:G6) -> 0 | H7: =IFERROR(C7/C$7,0) -> 0 | I7: =IFERROR(D7/D$7,0) -> 0 | J7: =IFERROR(E7/E$7,0) -> 0 | K7: =IFERROR(F7/F$7,0) -> 0 | L7: =IFERROR(G7/G$7,0) -> 0 | M7: =+IFERROR((D7/C7)-1,0) -> 0 | N7: =+IFERROR((E7/D7)-1,0) -> 0 | O7: =+IFERROR((F7/E7)-1,0) -> 0 | P7: =+IFERROR((G7/F7)-1,0) -> 0 | AH7: INR million
B8: % change y-o-y | D8: =IFERROR(D7/C7-1,0) -> 0 | E8: =IFERROR(E7/D7-1,0) -> 0 | F8: =IFERROR(F7/E7-1,0) -> 0 | G8: =IFERROR(G7/F7-1,0) -> 0
B9: Cost of goods sold | C9: =SUM(C10:C11) -> 0 | D9: =SUM(D10:D11) -> 0 | E9: =SUM(E10:E11) -> 0 | F9: =SUM(F10:F11) -> 0 | G9: =SUM(G10:G11) -> 0 | H9: =IFERROR(C9/C$7,0) -> 0 | I9: =IFERROR(D9/D$7,0) -> 0 | J9: =IFERROR(E9/E$7,0) -> 0 | K9: =IFERROR(F9/F$7,0) -> 0 | L9: =IFERROR(G9/G$7,0) -> 0 | M9: =+IFERROR((D9/C9)-1,0) -> 0 | N9: =+IFERROR((E9/D9)-1,0) -> 0 | O9: =+IFERROR((F9/E9)-1,0) -> 0 | P9: =+IFERROR((G9/F9)-1,0) -> 0
B10: Purchases | C10: =SUM(Sch.!C271:C272)/curr -> 0 | D10: =SUM(Sch.!D271:D272)/curr -> 0 | E10: =SUM(Sch.!E271:E272)/curr -> 0 | F10: =SUM(Sch.!F271:F272)/curr -> 0 | G10: =SUM(Sch.!G271:G272)/curr -> 0 | H10: =IFERROR(C10/C$7,0) -> 0 | I10: =IFERROR(D10/D$7,0) -> 0 | J10: =IFERROR(E10/E$7,0) -> 0 | K10: =IFERROR(F10/F$7,0) -> 0 | L10: =IFERROR(G10/G$7,0) -> 0 | M10: =+IFERROR((D10/C10)-1,0) -> 0 | N10: =+IFERROR((E10/D10)-1,0) -> 0 | O10: =+IFERROR((F10/E10)-1,0) -> 0 | P10: =+IFERROR((G10/F10)-1,0) -> 0
B11: Changes in inventories of finished goods | C11: =Sch.!C273/curr -> 0 | D11: =Sch.!D273/curr -> 0 | E11: =Sch.!E273/curr -> 0 | F11: =Sch.!F273/curr -> 0 | G11: =Sch.!G273/curr -> 0 | H11: =IFERROR(C11/C$7,0) -> 0 | I11: =IFERROR(D11/D$7,0) -> 0 | J11: =IFERROR(E11/E$7,0) -> 0 | K11: =IFERROR(F11/F$7,0) -> 0 | L11: =IFERROR(G11/G$7,0) -> 0 | M11: =+IFERROR((D11/C11)-1,0) -> 0 | N11: =+IFERROR((E11/D11)-1,0) -> 0 | O11: =+IFERROR((F11/E11)-1,0) -> 0 | P11: =+IFERROR((G11/F11)-1,0) -> 0
B12: Direct expenses | C12: =Sch.!C342/curr -> 0 | D12: =Sch.!D342/curr -> 0 | E12: =Sch.!E342/curr -> 0 | F12: =Sch.!F342/curr -> 0 | G12: =Sch.!G342/curr -> 0 | H12: =IFERROR(C12/C$7,0) -> 0 | I12: =IFERROR(D12/D$7,0) -> 0 | J12: =IFERROR(E12/E$7,0) -> 0 | K12: =IFERROR(F12/F$7,0) -> 0 | L12: =IFERROR(G12/G$7,0) -> 0 | M12: =+IFERROR((D12/C12)-1,0) -> 0 | N12: =+IFERROR((E12/D12)-1,0) -> 0 | O12: =+IFERROR((F12/E12)-1,0) -> 0 | P12: =+IFERROR((G12/F12)-1,0) -> 0
B13: Gross margin | C13: =C7-C9-C12 -> 0 | D13: =D7-D9-D12 -> 0 | E13: =E7-E9-E12 -> 0 | F13: =F7-F9-F12 -> 0 | G13: =G7-G9-G12 -> 0 | H13: =IFERROR(C13/C$7,0) -> 0 | I13: =IFERROR(D13/D$7,0) -> 0 | J13: =IFERROR(E13/E$7,0) -> 0 | K13: =IFERROR(F13/F$7,0) -> 0 | L13: =IFERROR(G13/G$7,0) -> 0 | M13: =+IFERROR((D13/C13)-1,0) -> 0 | N13: =+IFERROR((E13/D13)-1,0) -> 0 | O13: =+IFERROR((F13/E13)-1,0) -> 0 | P13: =+IFERROR((G13/F13)-1,0) -> 0
B14: Employee benefit expense | C14: =(Sch.!C301)/(curr) -> 0 | D14: =(Sch.!D301)/(curr) -> 0 | E14: =(Sch.!E301)/(curr) -> 0 | F14: =(Sch.!F301)/(curr) -> 0 | G14: =(Sch.!G301)/(curr) -> 0 | H14: =IFERROR(C14/C$7,0) -> 0 | I14: =IFERROR(D14/D$7,0) -> 0 | J14: =IFERROR(E14/E$7,0) -> 0 | K14: =IFERROR(F14/F$7,0) -> 0 | L14: =IFERROR(G14/G$7,0) -> 0 | M14: =+IFERROR((D14/C14)-1,0) -> 0 | N14: =+IFERROR((E14/D14)-1,0) -> 0 | O14: =+IFERROR((F14/E14)-1,0) -> 0 | P14: =+IFERROR((G14/F14)-1,0) -> 0
B15: Other expenses | C15: =(Sch.!C393+Sch.!C452)/curr -> 0 | D15: =(Sch.!D393+Sch.!D452)/curr -> 0 | E15: =(Sch.!E393+Sch.!E452)/curr -> 0 | F15: =(Sch.!F393+Sch.!F452)/curr -> 0 | G15: =(Sch.!G393+Sch.!G452)/curr -> 0 | H15: =IFERROR(C15/C$7,0) -> 0 | I15: =IFERROR(D15/D$7,0) -> 0 | J15: =IFERROR(E15/E$7,0) -> 0 | K15: =IFERROR(F15/F$7,0) -> 0 | L15: =IFERROR(G15/G$7,0) -> 0 | M15: =+IFERROR((D15/C15)-1,0) -> 0 | N15: =+IFERROR((E15/D15)-1,0) -> 0 | O15: =+IFERROR((F15/E15)-1,0) -> 0 | P15: =+IFERROR((G15/F15)-1,0) -> 0
B16: Operating EBITDA | C16: =C13-SUM(C14:C15) -> 0 | D16: =D13-SUM(D14:D15) -> 0 | E16: =E13-SUM(E14:E15) -> 0 | F16: =F13-SUM(F14:F15) -> 0 | G16: =G13-SUM(G14:G15) -> 0 | H16: =IFERROR(C16/C$7,0) -> 0 | I16: =IFERROR(D16/D$7,0) -> 0 | J16: =IFERROR(E16/E$7,0) -> 0 | K16: =IFERROR(F16/F$7,0) -> 0 | L16: =IFERROR(G16/G$7,0) -> 0 | M16: =+IFERROR((D16/C16)-1,0) -> 0 | N16: =+IFERROR((E16/D16)-1,0) -> 0 | O16: =+IFERROR((F16/E16)-1,0) -> 0 | P16: =+IFERROR((G16/F16)-1,0) -> 0
B17: Depreciation | C17: =(Sch.!C310)/(curr) -> 0 | D17: =(Sch.!D310)/(curr) -> 0 | E17: =(Sch.!E310)/(curr) -> 0 | F17: =(Sch.!F310)/(curr) -> 0 | G17: =(Sch.!G310)/(curr) -> 0 | H17: =IFERROR(C17/C$7,0) -> 0 | I17: =IFERROR(D17/D$7,0) -> 0 | J17: =IFERROR(E17/E$7,0) -> 0 | K17: =IFERROR(F17/F$7,0) -> 0 | L17: =IFERROR(G17/G$7,0) -> 0 | M17: =+IFERROR((D17/C17)-1,0) -> 0 | N17: =+IFERROR((E17/D17)-1,0) -> 0 | O17: =+IFERROR((F17/E17)-1,0) -> 0 | P17: =+IFERROR((G17/F17)-1,0) -> 0
B18: Finance cost | C18: =Sch.!C326/curr -> 0 | D18: =Sch.!D326/curr -> 0 | E18: =Sch.!E326/curr -> 0 | F18: =Sch.!F326/curr -> 0 | G18: =Sch.!G326/curr -> 0 | H18: =IFERROR(C18/C$7,0) -> 0 | I18: =IFERROR(D18/D$7,0) -> 0 | J18: =IFERROR(E18/E$7,0) -> 0 | K18: =IFERROR(F18/F$7,0) -> 0 | L18: =IFERROR(G18/G$7,0) -> 0 | M18: =+IFERROR((D18/C18)-1,0) -> 0 | N18: =+IFERROR((E18/D18)-1,0) -> 0 | O18: =+IFERROR((F18/E18)-1,0) -> 0 | P18: =+IFERROR((G18/F18)-1,0) -> 0
B19: Operating PBT | C19: =C16-SUM(C17:C18) -> 0 | D19: =D16-SUM(D17:D18) -> 0 | E19: =E16-SUM(E17:E18) -> 0 | F19: =F16-SUM(F17:F18) -> 0 | G19: =G16-SUM(G17:G18) -> 0 | H19: =IFERROR(C19/C$7,0) -> 0 | I19: =IFERROR(D19/D$7,0) -> 0 | J19: =IFERROR(E19/E$7,0) -> 0 | K19: =IFERROR(F19/F$7,0) -> 0 | L19: =IFERROR(G19/G$7,0) -> 0 | M19: =+IFERROR((D19/C19)-1,0) -> 0 | N19: =+IFERROR((E19/D19)-1,0) -> 0 | O19: =+IFERROR((F19/E19)-1,0) -> 0 | P19: =+IFERROR((G19/F19)-1,0) -> 0
B20: Non operating income | C20: =((Sch.!C268))/(curr) -> 0 | D20: =((Sch.!D268))/(curr) -> 0 | E20: =((Sch.!E268))/(curr) -> 0 | F20: =((Sch.!F268))/(curr) -> 0 | G20: =((Sch.!G268))/(curr) -> 0 | H20: =IFERROR(C20/C$7,0) -> 0 | I20: =IFERROR(D20/D$7,0) -> 0 | J20: =IFERROR(E20/E$7,0) -> 0 | K20: =IFERROR(F20/F$7,0) -> 0 | L20: =IFERROR(G20/G$7,0) -> 0 | M20: =+IFERROR((D20/C20)-1,0) -> 0 | N20: =+IFERROR((E20/D20)-1,0) -> 0 | O20: =+IFERROR((F20/E20)-1,0) -> 0 | P20: =+IFERROR((G20/F20)-1,0) -> 0
B21: Tax expense | C21: =Sch.!C338/curr -> 0 | D21: =Sch.!D338/curr -> 0 | E21: =Sch.!E338/curr -> 0 | F21: =Sch.!F338/curr -> 0 | G21: =Sch.!G338/curr -> 0 | H21: =IFERROR(C21/C$7,0) -> 0 | I21: =IFERROR(D21/D$7,0) -> 0 | J21: =IFERROR(E21/E$7,0) -> 0 | K21: =IFERROR(F21/F$7,0) -> 0 | L21: =IFERROR(G21/G$7,0) -> 0 | M21: =+IFERROR((D21/C21)-1,0) -> 0 | N21: =+IFERROR((E21/D21)-1,0) -> 0 | O21: =+IFERROR((F21/E21)-1,0) -> 0 | P21: =+IFERROR((G21/F21)-1,0) -> 0
B22: PAT | C22: =C19+C20-C21 -> 0 | D22: =D19+D20-D21 -> 0 | E22: =E19+E20-E21 -> 0 | F22: =F19+F20-F21 -> 0 | G22: =G19+G20-G21 -> 0 | H22: =IFERROR(C22/C$7,0) -> 0 | I22: =IFERROR(D22/D$7,0) -> 0 | J22: =IFERROR(E22/E$7,0) -> 0 | K22: =IFERROR(F22/F$7,0) -> 0 | L22: =IFERROR(G22/G$7,0) -> 0 | M22: =+IFERROR((D22/C22)-1,0) -> 0 | N22: =+IFERROR((E22/D22)-1,0) -> 0 | O22: =+IFERROR((F22/E22)-1,0) -> 0 | P22: =+IFERROR((G22/F22)-1,0) -> 0
B24: As per financials
B25: Difference | C25: =C22-C24 -> 0 | D25: =D22-D24 -> 0 | E25: =E22-E24 -> 0 | F25: =F22-F24 -> 0 | G25: =G22-G24 -> 0

Sheet BS
B2: =IS!B2 -> Name
B3: Balance sheet
B4: =IS!B4 -> INR million
B5: Particulars | C5: 31 Mar 22 | D5: 31 Mar 23 | E5: 31 Mar 24 | F5: 31 Mar 25 | G5: 31 Mar 26
B6: Equity & liabilities
B7: Shareholder's fund
B8: Share capital | C8: =((Sch.!C11))/(curr) -> 0 | D8: =((Sch.!D11))/(curr) -> 0 | E8: =((Sch.!E11))/(curr) -> 0 | F8: =((Sch.!F11))/(curr) -> 0 | G8: =((Sch.!G11))/(curr) -> 0
B9: Reserves and surplus | C9: =(Sch.!C22)/(curr) -> 0 | D9: =(Sch.!D22)/(curr) -> 0 | E9: =(Sch.!E22)/(curr) -> 0 | F9: =(Sch.!F22)/(curr) -> 0 | G9: =(Sch.!G22)/(curr) -> 0
B10: Net worth | C10: =SUM(C8:C9) -> 0 | D10: =SUM(D8:D9) -> 0 | E10: =SUM(E8:E9) -> 0 | F10: =SUM(F8:F9) -> 0 | G10: =SUM(G8:G9) -> 0
B11: Long-term borrowings | C11: =Sch.!C43/curr -> 0 | D11: =Sch.!D43/curr -> 0 | E11: =Sch.!E43/curr -> 0 | F11: =Sch.!F43/curr -> 0 | G11: =Sch.!G43/curr -> 0
B12: Short-term borrowings | C12: =Sch.!C69/curr -> 0 | D12: =Sch.!D69/curr -> 0 | E12: =Sch.!E69/curr -> 0 | F12: =Sch.!F69/curr -> 0 | G12: =Sch.!G69/curr -> 0
B13: Borrowings | C13: =SUM(C11:C12) -> 0 | D13: =SUM(D11:D12) -> 0 | E13: =SUM(E11:E12) -> 0 | F13: =SUM(F11:F12) -> 0 | G13: =SUM(G11:G12) -> 0
B14: Total | C14: =C10+C13 -> 0 | D14: =D10+D13 -> 0 | E14: =E10+E13 -> 0 | F14: =F10+F13 -> 0 | G14: =G10+G13 -> 0
B15: Assets
B16: Tangible assets | C16: =Sch.!C128/curr -> 0 | D16: =Sch.!D128/curr -> 0 | E16: =Sch.!E128/curr -> 0 | F16: =Sch.!F128/curr -> 0 | G16: =Sch.!G128/curr -> 0
B17: Deferred tax assets (net) | C17: =Sch.!C204/curr -> 0 | D17: =Sch.!D204/curr -> 0 | E17: =Sch.!E204/curr -> 0 | F17: =Sch.!F204/curr -> 0 | G17: =Sch.!G204/curr -> 0
B18: Current and non-current investments | C18: =(Sch.!C154+Sch.!C159)/curr -> 0 | D18: =(Sch.!D154+Sch.!D159)/curr -> 0 | E18: =(Sch.!E154+Sch.!E159)/curr -> 0 | F18: =(Sch.!F154+Sch.!F159)/curr -> 0 | G18: =(Sch.!G154+Sch.!G159)/curr -> 0
B19: Cash and cash equivalents | C19: =((Sch.!C198))/(curr) -> 0 | D19: =((Sch.!D198))/(curr) -> 0 | E19: =((Sch.!E198))/(curr) -> 0 | F19: =((Sch.!F198))/(curr) -> 0 | G19: =((Sch.!G198))/(curr) -> 0
B20: Current assets
B21: Trade receivables | C21: =((Sch.!C171))/(curr) -> 0 | D21: =((Sch.!D171))/(curr) -> 0 | E21: =((Sch.!E171))/(curr) -> 0 | F21: =((Sch.!F171))/(curr) -> 0 | G21: =((Sch.!G171))/(curr) -> 0
B22: Inventories | C22: =Sch.!C185/curr -> 0 | D22: =Sch.!D185/curr -> 0 | E22: =Sch.!E185/curr -> 0 | F22: =Sch.!F185/curr -> 0 | G22: =Sch.!G185/curr -> 0
B23: Long-term loans and advances | C23: =Sch.!C143/curr -> 0 | D23: =Sch.!D143/curr -> 0 | E23: =Sch.!E143/curr -> 0 | F23: =Sch.!F143/curr -> 0 | G23: =Sch.!G143/curr -> 0
B24: Short term loan and advances | C24: =(Sch.!C221)/(curr) -> 0 | D24: =(Sch.!D221)/(curr) -> 0 | E24: =(Sch.!E221)/(curr) -> 0 | F24: =(Sch.!F221)/(curr) -> 0 | G24: =(Sch.!G221)/(curr) -> 0
B25: Other current assets | C25: =(Sch.!C238)/(curr) -> 0 | D25: =(Sch.!D238)/(curr) -> 0 | E25: =(Sch.!E238)/(curr) -> 0 | F25: =(Sch.!F238)/(curr) -> 0 | G25: =(Sch.!G238)/(curr) -> 0
B26: Current assets | C26: =SUM(C21:C25) -> 0 | D26: =SUM(D21:D25) -> 0 | E26: =SUM(E21:E25) -> 0 | F26: =SUM(F21:F25) -> 0 | G26: =SUM(G21:G25) -> 0
B27: Current Liabilities
B28: Trade payables | C28: =(Sch.!C55)/(curr) -> 0 | D28: =(Sch.!D55)/(curr) -> 0 | E28: =(Sch.!E55)/(curr) -> 0 | F28: =(Sch.!F55)/(curr) -> 0 | G28: =(Sch.!G55)/(curr) -> 0
B29: Other current liabilities | C29: =(Sch.!C103)/(curr) -> 0 | D29: =(Sch.!D103)/(curr) -> 0 | E29: =(Sch.!E103)/(curr) -> 0 | F29: =(Sch.!F103)/(curr) -> 0 | G29: =(Sch.!G103)/(curr) -> 0
B30: Long-term provisions | C30: =Sch.!C31/curr -> 0 | D30: =Sch.!D31/curr -> 0 | E30: =Sch.!E31/curr -> 0 | F30: =Sch.!F31/curr -> 0 | G30: =Sch.!G31/curr -> 0
B31: Short-term provisions | C31: =(Sch.!C82)/(curr) -> 0 | D31: =(Sch.!D82)/(curr) -> 0 | E31: =(Sch.!E82)/(curr) -> 0 | F31: =(Sch.!F82)/(curr) -> 0 | G31: =(Sch.!G82)/(curr) -> 0
B32: Current liabilities | C32: =SUM(C28:C31) -> 0 | D32: =SUM(D28:D31) -> 0 | E32: =SUM(E28:E31) -> 0 | F32: =SUM(F28:F31) -> 0 | G32: =SUM(G28:G31) -> 0
B33: Net current assets | C33: =C26-C32 -> 0 | D33: =D26-D32 -> 0 | E33: =E26-E32 -> 0 | F33: =F26-F32 -> 0 | G33: =G26-G32 -> 0
B34: Total | C34: =SUM(C16:C19,C33) -> 0 | D34: =SUM(D16:D19,D33) -> 0 | E34: =SUM(E16:E19,E33) -> 0 | F34: =SUM(F16:F19,F33) -> 0 | G34: =SUM(G16:G19,G33) -> 0
B36: Check | C36: =C14-C34 -> 0 | D36: =D14-D34 -> 0 | E36: =E14-E34 -> 0 | F36: =F14-F34 -> 0 | G36: =G14-G34 -> 0

Sheet CF
B2: =IS!B2 -> Name
B3: Cashflow statements
B4: =IS!B4 -> INR million
B5: Particulars | C5: =IS!D5 -> FY23 | D5: =IS!E5 -> FY24 | E5: =IS!F5 -> FY25 | F5: =IS!G5 -> FY26
B6: Cashflow from operating activities
B7: Net profit after tax | C7: =IS!D22 -> 0 | D7: =IS!E22 -> 0 | E7: =IS!F22 -> 0 | F7: =IS!G22 -> 0
B8: Depreciation | C8: =IS!D17 -> 0 | D8: =IS!E17 -> 0 | E8: =IS!F17 -> 0 | F8: =IS!G17 -> 0
B9: Operating profit before working capital changes | C9: =SUM(C7:C8) -> 0 | D9: =SUM(D7:D8) -> 0 | E9: =SUM(E7:E8) -> 0 | F9: =SUM(F7:F8) -> 0
B10: (Increase)/decrease in receivables | C10: =BS!C21-BS!D21 -> 0 | D10: =BS!D21-BS!E21 -> 0 | E10: =BS!E21-BS!F21 -> 0 | F10: =BS!F21-BS!G21 -> 0
B11: (Increase)/decrease in short term loans and advances | C11: =+BS!C24-BS!D24 -> 0 | D11: =+BS!D24-BS!E24 -> 0 | E11: =+BS!E24-BS!F24 -> 0 | F11: =+BS!F24-BS!G24 -> 0
B12: (Increase)/decrease in other current assets | C12: =BS!C25-BS!D25 -> 0 | D12: =BS!D25-BS!E25 -> 0 | E12: =BS!E25-BS!F25 -> 0 | F12: =BS!F25-BS!G25 -> 0
B13: (Increase)/decrease in inventories | C13: =BS!C22-BS!D22 -> 0 | D13: =BS!D22-BS!E22 -> 0 | E13: =BS!E22-BS!F22 -> 0 | F13: =BS!F22-BS!G22 -> 0
B14: (Increase)/decrease in long term loans and advances | C14: =BS!C23-BS!D23 -> 0 | D14: =BS!D23-BS!E23 -> 0 | E14: =BS!E23-BS!F23 -> 0 | F14: =BS!F23-BS!G23 -> 0
B15: (Increase)/decrease in deferred tax assets | C15: =BS!C17-BS!D17 -> 0 | D15: =BS!D17-BS!E17 -> 0 | E15: =BS!E17-BS!F17 -> 0 | F15: =BS!F17-BS!G17 -> 0
B16: Increase/(decrease) in trade payables | C16: =BS!D28-BS!C28 -> 0 | D16: =BS!E28-BS!D28 -> 0 | E16: =BS!F28-BS!E28 -> 0 | F16: =BS!G28-BS!F28 -> 0
B17: Increase/(decrease) in other current liabilities | C17: =BS!D29-BS!C29 -> 0 | D17: =BS!E29-BS!D29 -> 0 | E17: =BS!F29-BS!E29 -> 0 | F17: =BS!G29-BS!F29 -> 0
B18: Increase/(decrease) in short term provision | C18: =BS!D31-BS!C31 -> 0 | D18: =BS!E31-BS!D31 -> 0 | E18: =BS!F31-BS!E31 -> 0 | F18: =BS!G31-BS!F31 -> 0
B19: Increase/(decrease) in long term provision | C19: =BS!D30-BS!C30 -> 0 | D19: =BS!E30-BS!D30 -> 0 | E19: =BS!F30-BS!E30 -> 0 | F19: =BS!G30-BS!F30 -> 0
B20: Net cash from (used in) operating activities | C20: =SUM(C9:C19) -> 0 | D20: =SUM(D9:D19) -> 0 | E20: =SUM(E9:E19) -> 0 | F20: =SUM(F9:F19) -> 0
B21: Cashflow from investing activities
B22: (Purchase)/sale of fixed assets | C22: =BS!C16-BS!D16-IS!D17 -> 0 | D22: =BS!D16-IS!E17-BS!E16 -> 0 | E22: =BS!E16-IS!F17-BS!F16 -> 0 | F22: =BS!F16-IS!G17-BS!G16 -> 0
B23: (Increase)/decrease in non-current investment | C23: =BS!C18-BS!D18 -> 0 | D23: =BS!D18-BS!E18 -> 0 | E23: =BS!E18-BS!F18 -> 0 | F23: =BS!F18-BS!G18 -> 0
B24: Net cash from (used in) investing activities | C24: =SUM(C22:C23) -> 0 | D24: =SUM(D22:D23) -> 0 | E24: =SUM(E22:E23) -> 0 | F24: =SUM(F22:F23) -> 0
B25: Cashflow from financing activities
B26: Changes in reserves | C26: =BS!D9-BS!C9-IS!D22 -> 0 | D26: =BS!E9-BS!D9-IS!E22 -> 0 | E26: =BS!F9-BS!E9-IS!F22 -> 0 | F26: =BS!G9-BS!F9-IS!G22 -> 0
B27: Increase/(decrease) in long term borrowings | C27: =BS!D11-BS!C11 -> 0 | D27: =BS!E11-BS!D11 -> 0 | E27: =BS!F11-BS!E11 -> 0 | F27: =BS!G11-BS!F11 -> 0
B28: Increase/(decrease) in short term borrowings | C28: =BS!D12-BS!C12 -> 0 | D28: =BS!E12-BS!D12 -> 0 | E28: =BS!F12-BS!E12 -> 0 | F28: =BS!G12-BS!F12 -> 0
B29: Net cash from (used in) financing activities | C29: =SUM(C26:C28) -> 0 | D29: =SUM(D26:D28) -> 0 | E29: =SUM(E26:E28) -> 0 | F29: =SUM(F26:F28) -> 0
B30: Increase/(decrease) in cash and cash equivalents | C30: =C20+C24+C29 -> 0 | D30: =D20+D24+D29 -> 0 | E30: =E20+E24+E29 -> 0 | F30: =F20+F24+F29 -> 0
B31: Opening cash and cash equivalents | C31: =BS!C19 -> 0 | D31: =BS!D19 -> 0 | E31: =BS!E19 -> 0 | F31: =BS!F19 -> 0
B32: Closing cash and cash equivalents | C32: =SUM(C30:C31) -> 0 | D32: =SUM(D30:D31) -> 0 | E32: =SUM(E30:E31) -> 0 | F32: =SUM(F30:F31) -> 0
B34: Closing cash and cash equivalents | C34: =BS!D19 -> 0 | D34: =BS!E19 -> 0 | E34: =BS!F19 -> 0 | F34: =BS!G19 -> 0
B35: Check | C35: =C32-C34 -> 0 | D35: =D32-D34 -> 0 | E35: =E32-E34 -> 0 | F35: =F32-F34 -> 0

Sheet Sch.
B2: =IS!B2 -> Name
B3: Notes to accounts
B4: =IS!B4 -> INR million
B5: Share capital
B6: Particulars | C6: FY22 | D6: FY23 | E6: FY24 | F6: FY25 | G6: FY26
B7: Authorised
B8: "x" equity shares of Rs. 10 each
B9: Issued, subscribed and paid up
B10: "x" equity shares of Rs. 10 each
B11: Total | C11: =C10 -> 0 | D11: =D10 -> 0 | E11: =E10 -> 0 | F11: =F10 -> 0 | G11: =G10 -> 0
B12: Reserves and surplus
B13: Particulars | C13: =C6 -> FY22 | D13: =D6 -> FY23 | E13: =E6 -> FY24 | F13: =F6 -> FY25 | G13: =G6 -> FY26
B14: Securities premium
B15: Other reserves
B16: Surplus
B17: Opening balance | D17: =C21 -> 0 | E17: =D21 -> 0 | F17: =E21 -> 0 | G17: =F21 -> 0
B18: Less: Income tax paid
B19: Additions during the year
B20: Profit for the year | C20: =IS!C22*curr -> 0 | D20: =IS!D22*curr -> 0 | E20: =IS!E22*curr -> 0 | F20: =IS!F22*curr -> 0 | G20: =IS!G22*curr -> 0
B21: Closing balance | C21: =SUM(C17:C20) -> 0 | D21: =SUM(D17:D20) -> 0 | E21: =SUM(E17:E20) -> 0 | F21: =SUM(F17:F20) -> 0 | G21: =SUM(G17:G20) -> 0
B22: Total | C22: =C14+C15+C21 -> 0 | D22: =D14+D15+D21 -> 0 | E22: =E14+E15+E21 -> 0 | F22: =F14+F15+F21 -> 0 | G22: =G14+G15+G21 -> 0
B24: Long term provisions
B25: Particulars | C25: =C6 -> FY22 | D25: =D6 -> FY23 | E25: =E6 -> FY24 | F25: =F6 -> FY25 | G25: =G6 -> FY26
B26: Provision for gratuity
B30: Provision for leave encashment
B31: Total | C31: =SUM(C26:C30) -> 0 | D31: =SUM(D26:D30) -> 0 | E31: =SUM(E26:E30) -> 0 | F31: =SUM(F26:F30) -> 0 | G31: =SUM(G26:G30) -> 0
B33: Long term borrowings
B34: Particulars | C34: =C6 -> FY22 | D34: =D6 -> FY23 | E34: =E6 -> FY24 | F34: =F6 -> FY25 | G34: =G6 -> FY26
B35: Director's loan a/c
B42: Term loan
B43: Total | C43: =SUM(C35:C42) -> 0 | D43: =SUM(D35:D42) -> 0 | E43: =SUM(E35:E42) -> 0 | F43: =SUM(F35:F42) -> 0 | G43: =SUM(G35:G42) -> 0
B45: Trade payables
B46: Particulars | C46: =C6 -> FY22 | D46: =D6 -> FY23 | E46: =E6 -> FY24 | F46: =F6 -> FY25 | G46: =G6 -> FY26
B47: Sundry creditors for goods
B48: Sundry creditors for other than goods
B54: Advance from customers (Interest free)
B55: Total | C55: =SUM(C47:C54) -> 0 | D55: =SUM(D47:D54) -> 0 | E55: =SUM(E47:E54) -> 0 | F55: =SUM(F47:F54) -> 0 | G55: =SUM(G47:G54) -> 0
B57: Short term borrowings
B58: Particulars | C58: =C6 -> FY22 | D58: =D6 -> FY23 | E58: =E6 -> FY24 | F58: =F6 -> FY25 | G58: =G6 -> FY26
B59: Secured loan from banks
...

Sheet Ratios
B2: Key ratio analysis:
B3: Particulars | C3: Formula | D3: =IS!C5 -> FY22 | E3: =IS!D5 -> FY23 | F3: =IS!E5 -> FY24 | G3: =IS!F5 -> FY25 | H3: =IS!G5 -> FY26
B4: Current ratio | C4: Current assets/ current liabilities | D4: =IFERROR(BS!C26/BS!C32,0) -> 0 | E4: =IFERROR(BS!D26/BS!D32,0) -> 0 | F4: =IFERROR(BS!E26/BS!E32,0) -> 0 | G4: =IFERROR(BS!F26/BS!F32,0) -> 0 | H4: =IFERROR(BS!G26/BS!G32,0) -> 0
B5: Current Ratio
B6: Fixed assets turnover ratio | C6: Total revenue/ total fixed assets | D6: =IFERROR(IS!C7/BS!C16,0) -> 0 | E6: =IFERROR(IS!D7/BS!D16,0) -> 0 | F6: =IFERROR(IS!E7/BS!E16,0) -> 0 | G6: =IFERROR(IS!F7/BS!F16,0) -> 0 | H6: =IFERROR(IS!G7/BS!G16,0) -> 0
B7: Pre-tax ROCE (%) | C7: EBIT/ closing adjusted capital employed | D7: =IFERROR((IS!C19+IS!C18)/(BS!C10+BS!C13-BS!C19-BS!C18),0) -> 0 | E7: =IFERROR((IS!D19+IS!D18)/(BS!D10+BS!D13-BS!D19-BS!D18),0) -> 0 | F7: =IFERROR((IS!E19+IS!E18)/(BS!E10+BS!E13-BS!E19-BS!E18),0) -> 0 | G7: =IFERROR((IS!F19+IS!F18)/(BS!F10+BS!F13-BS!F19-BS!F18),0) -> 0 | H7: =IFERROR((IS!G19+IS!G18)/(BS!G10+BS!G13-BS!G19-BS!G18),0) -> 0
B8: Pre-tax ROE (%) | C8: PBT/ closing adjusted net worth | D8: =IFERROR((IS!C19)/(BS!C10-BS!C19-BS!C18),0) -> 0 | E8: =IFERROR((IS!D19)/(BS!D10-BS!D19-BS!D18),0) -> 0 | F8: =IFERROR((IS!E19)/(BS!E10-BS!E19-BS!E18),0) -> 0 | G8: =IFERROR((IS!F19)/(BS!F10-BS!F19-BS!F18),0) -> 0 | H8: =IFERROR((IS!G19)/(BS!G10-BS!G19-BS!G18),0) -> 0
B9: Operating EBITDA margin (%) | C9: Operating EBITDA/ total revenue | D9: =IS!H16 -> 0 | E9: =IS!I16 -> 0 | F9: =IS!J16 -> 0 | G9: =IS!K16 -> 0 | H9: =IS!L16 -> 0
B10: Operating PBT margin (%) | C10: Operating PBT/ total revenue | D10: =IS!H19 -> 0 | E10: =IS!I19 -> 0 | F10: =IS!J19 -> 0 | G10: =IS!K19 -> 0 | H10: =IS!L19 -> 0
B13: Cash conversion cycle:
B14: Particulars | C14: Formula | D14: =D3 -> FY22 | E14: =E3 -> FY23 | F14: =F3 -> FY24 | G14: =G3 -> FY25 | H14: =H3 -> FY26
B15: Receivables days | C15: (Closing receivables / Turnover)*365 | D15: =IFERROR(BS!C21/IS!C7*365,0) -> 0 | E15: =IFERROR(BS!D21/IS!D7*365,0) -> 0 | F15: =IFERROR(BS!E21/IS!E7*365,0) -> 0 | G15: =IFERROR(BS!F21/IS!F7*365,0) -> 0 | H15: =IFERROR(BS!G21/IS!G7*365,0) -> 0
B16: Inventory days | C16: (Closing inventory / Turnover)*365 | D16: =IFERROR(BS!C22/IS!C7*365,0) -> 0 | E16: =IFERROR(BS!D22/IS!D7*365,0) -> 0 | F16: =IFERROR(BS!E22/IS!E7*365,0) -> 0 | G16: =IFERROR(BS!F22/IS!F7*365,0) -> 0 | H16: =IFERROR(BS!G22/IS!G7*365,0) -> 0
B17: OCA, L&A days | C17: (Closing OCA, L&A / Turnover)*365 | D17: =IFERROR((BS!C23+BS!C24+BS!C25)/IS!C7*365,0) -> 0 | E17: =IFERROR((BS!D23+BS!D24+BS!D25)/IS!D7*365,0) -> 0 | F17: =IFERROR((BS!E23+BS!E24+BS!E25)/IS!E7*365,0) -> 0 | G17: =IFERROR((BS!F23+BS!F24+BS!F25)/IS!F7*365,0) -> 0 | H17: =IFERROR((BS!G23+BS!G24+BS!G25)/IS!G7*365,0) -> 0
B18: Payable days | C18: (Closing payables / Turnover)*365 | D18: =IFERROR(BS!C28/IS!C7*365,0) -> 0 | E18: =IFERROR(BS!D28/IS!D7*365,0) -> 0 | F18: =IFERROR(BS!E28/IS!E7*365,0) -> 0 | G18: =IFERROR(BS!F28/IS!F7*365,0) -> 0 | H18: =IFERROR(BS!G28/IS!G7*365,0) -> 0
B19: OCL, Provisions days | C19: (Closing OCL, Provisions / Turnover)*365 | D19: =IFERROR((BS!C29+BS!C30+BS!C31)/IS!C7*365,0) -> 0 | E19: =IFERROR((BS!D29+BS!D30+BS!D31)/IS!D7*365,0) -> 0 | F19: =IFERROR((BS!E29+BS!E30+BS!E31)/IS!E7*365,0) -> 0 | G19: =IFERROR((BS!F29+BS!F30+BS!F31)/IS!F7*365,0) -> 0 | H19: =IFERROR((BS!G29+BS!G30+BS!G31)/IS!G7*365,0) -> 0
B20: Net cash conversion cycle | D20: =SUM(D15:D17)-D18-D19 -> 0 | E20: =SUM(E15:E17)-E18-E19 -> 0 | F20: =SUM(F15:F17)-F18-F19 -> 0 | G20: =SUM(G15:G17)-G18-G19 -> 0 | H20: =SUM(H15:H17)-H18-H19 -> 0
C22: Net current asset days/ working capital days/ cash conversion cycle | D22: =IFERROR(BS!C33/IS!C7*365,0) -> 0 | E22: =IFERROR(BS!D33/IS!D7*365,0) -> 0 | F22: =IFERROR(BS!E33/IS!E7*365,0) -> 0 | G22: =IFERROR(BS!F33/IS!F7*365,0) -> 0 | H22: =IFERROR(BS!G33/IS!G7*365,0) -> 0
